<?xml version="1.0"?>
<sdf version="1.6">
  <model name="rmf_owl">
    <link name="body">
      <pose>0 0 0 0 0 0</pose>
      <inertial>
        <!-- The total mass is 1.5 kg due to the rotor mass. -->
        <mass>1.48</mass>
        <inertia>
          <ixx>0.017</ixx>
          <ixy>0</ixy>
          <ixz>0</ixz>
          <iyy>0.018</iyy>
          <iyz>0</iyz>
          <izz>0.028</izz>
        </inertia>
      </inertial>
      <collision name="body_collision">
        <pose>0 0 0.0165 0 0 0</pose>
        <geometry>
          <box>
            <size>0.3390 0.3800 0.2250</size>
          </box>
        </geometry>
      </collision>
      <visual name="body_visual">
        <geometry>
          <mesh>
            <uri>meshes/rmf_owl.dae</uri>
          </mesh>
        </geometry>
      </visual>

      <sensor name="px4_imu" type="imu">
          <pose> 0 0 0 0 0 0 </pose>
          <always_on>true</always_on>
          <topic>imu</topic>
          <update_rate>200</update_rate>
      </sensor>

      <sensor name="imu_sensor" type="imu">
          <pose>0.1005 0.0178 -0.0299 -1.5707963 0 -1.5707963</pose>
          <!--<pose> 0 0 0 0 0 0 </pose>-->
          <always_on>true</always_on>
          <topic>okvis_imu</topic>
          <update_rate>200</update_rate>
          <imu>
              <!--
                  <mean> and <std> are parameters of Gaussian noise
                  <bias_mean> and <bias_stddev> are parameters of Gaussian bias
                  <dynamic_bias_stddev> and <dynamic_bias_correlation_time> are parameters of noise, which drives slow derivation of sensor bias
                  <precision> is the precision of Gaussian quantized output signal
              -->
              <angular_velocity>
                  <x>
                      <noise type="gaussian">
                          <mean>0</mean>
                          <stddev>0.00</stddev>
                          <bias_mean>0.00</bias_mean>
                          <bias_stddev>0.00</bias_stddev>
                          <dynamic_bias_stddev>0.00</dynamic_bias_stddev>
                          <dynamic_bias_correlation_time>400.0</dynamic_bias_correlation_time>
                          <precision>0.00</precision>
                      </noise>
                  </x>
                  <y>
                      <noise type="gaussian">
                          <mean>0</mean>
                          <stddev>0.00</stddev>
                          <bias_mean>0.00</bias_mean>
                          <bias_stddev>0.00</bias_stddev>
                          <dynamic_bias_stddev>0.00</dynamic_bias_stddev>
                          <dynamic_bias_correlation_time>400.0</dynamic_bias_correlation_time>
                          <precision>0.00</precision>
                      </noise>
                  </y>
                  <z>
                      <noise type="gaussian">
                          <mean>0</mean>
                          <stddev>0.00</stddev>
                          <bias_mean>0.00</bias_mean>
                          <bias_stddev>0.00</bias_stddev>
                          <dynamic_bias_stddev>0.00</dynamic_bias_stddev>
                          <dynamic_bias_correlation_time>400.0</dynamic_bias_correlation_time>
                          <precision>0.00</precision>
                      </noise>
                  </z>
              </angular_velocity>
              <linear_acceleration>
                  <x>
                      <noise type="gaussian">
                          <mean>0.0</mean>
                          <stddev>0.00</stddev>
                          <bias_mean>0.0</bias_mean>
                          <bias_stddev>0.00</bias_stddev>
                          <dynamic_bias_stddev>0.00</dynamic_bias_stddev>
                          <dynamic_bias_correlation_time>175.0</dynamic_bias_correlation_time>
                          <precision>0.00</precision>
                      </noise>
                  </x>
                  <y>
                      <noise type="gaussian">
                          <mean>0.0</mean>
                          <stddev>0.00</stddev>
                          <bias_mean>0.0</bias_mean>
                          <bias_stddev>0.00</bias_stddev>
                          <dynamic_bias_stddev>0.00</dynamic_bias_stddev>
                          <dynamic_bias_correlation_time>175.0</dynamic_bias_correlation_time>
                          <precision>0.00</precision>
                      </noise>
                  </y>
                  <z>
                      <noise type="gaussian">
                          <mean>0.0</mean>
                          <stddev>0.00</stddev>
                          <bias_mean>0.0</bias_mean>
                          <bias_stddev>0.00</bias_stddev>
                          <dynamic_bias_stddev>0.00</dynamic_bias_stddev>
                          <dynamic_bias_correlation_time>175.0</dynamic_bias_correlation_time>
                          <precision>0.00</precision>
                      </noise>
                  </z>
              </linear_acceleration>
          </imu>
      </sensor>

      <!--Depth of realsense-->
      <sensor name="camera_depth" type="depth_camera">
        <pose>0.1165 0.04802 -0.0373 0 0 0</pose>
        <update_rate>15</update_rate>
        <camera name="camera_depth">
            <horizontal_fov>1.37274</horizontal_fov>
            <lens> <!--
                calculation of horizontal_fov:
                h_fov = 2*tan-1(width/(2*fx))
                -->
                <intrinsics>
                    <fx>390.598938</fx>
                    <fy>390.598938</fy>
                    <cx>320.0</cx>
                    <cy>240.0</cy>
                    <s>0</s>
                </intrinsics>
            </lens>
            <image> <!--Acceptable image resolutions and frequency of the D455 can be found in page 71 here https://www.intelrealsense.com/wp-content/uploads/2022/03/Intel-RealSense-D400-Series-Datasheet-March-2022.pdf-->
                <width>640</width>
                <height>480</height>
                <format>R_FLOAT32</format>
            </image>
            <clip>
                <near>0.4</near>
                <far>20.0</far>
            </clip>
        </camera>
      </sensor>

      <!--RGB camera of realsense-->
      <sensor name="rgb_camera" type="camera">
          <pose>0.1165 0.04802 -0.0373 0 0 0</pose>
          <always_on>true</always_on>
          <update_rate>10</update_rate>
          <visualize>true</visualize>
          <camera name="rgb_camera">
              <!--
                  calculation of horizontal_fov:
                  h_fov = 2*tan-1(width/(2*fx))
              -->
              <horizontal_fov>1.37274</horizontal_fov> 
              <lens>
                  <intrinsics>
                      <fx>390.598938</fx>
                      <fy>390.598938</fy>
                      <cx>320.581665</cx>
                      <cy>237.712845</cy>
                      <s>0</s>
                  </intrinsics>
              </lens>
              <image>
                  <width>640</width>
                  <height>480</height>
                  <format>R8G8B8</format>
              </image>
              <noise>
						    <type>gaussian</type>
						    <mean>0.0</mean>
						    <stddev>0.0</stddev>
					    </noise>
          </camera>
      </sensor>

       <!--Left camera of realsense-->
      <sensor name="camera_left" type="camera">
          <pose>0.1165 0.04802 -0.0373 0 0 0</pose>
          <always_on>true</always_on>
          <update_rate>10</update_rate>
          <visualize>true</visualize>
          <camera name="camera_left">
              <!--
                  calculation of horizontal_fov:
                  h_fov = 2*tan-1(width/(2*fx))
              -->
              <horizontal_fov>1.37274</horizontal_fov> 
              <lens>
                  <intrinsics>
                      <fx>390.598938</fx>
                      <fy>390.598938</fy>
                      <cx>320.581665</cx>
                      <cy>237.712845</cy>
                      <s>0</s>
                  </intrinsics>
              </lens>
              <image>
                  <width>640</width>
                  <height>480</height>
                  <format>R8G8B8</format>
              </image>
              <noise>
						    <type>gaussian</type>
						    <mean>0.0</mean>
						    <stddev>0.0</stddev>
					    </noise>
          </camera>
      </sensor>

      <!--Right camera of realsense-->
      <sensor name="camera_right" type="camera">
          <pose>0.1165 -0.04689012 -0.0373 0 0 0</pose>
          <always_on>true</always_on>
          <update_rate>10</update_rate>
          <visualize>true</visualize>
          <camera name="camera_right">
              <!--
                  calculation of horizontal_fov:
                  h_fov = 2*tan-1(width/(2*fx))
              -->
              <horizontal_fov>1.37274</horizontal_fov>
              <lens>
                  <intrinsics>
                      <fx>390.598938</fx>
                      <fy>390.598938</fy>
                      <cx>320.581665</cx>
                      <cy>237.712845</cy>
                      <s>0</s>
                  </intrinsics>
              </lens>
              <image>
                  <width>640</width>
                  <height>480</height>
                  <format>R8G8B8</format>
              </image>
          </camera>
      </sensor>

    <!--<sensor name="front_laser" type="gpu_ray">
          <pose>0 0 0.05 0 0 0</pose>
          <update_rate>3</update_rate>
          <visualize>true</visualize>
          <always_on>true</always_on>
          <ray>
              <scan>
                  <horizontal>
                      <samples>360</samples>
                      <resolution>1</resolution>
                      <min_angle>-3.1415</min_angle>
                      <max_angle>3.1415</max_angle>
                  </horizontal>
                  <vertical>
                      <samples>180</samples>
                      <resolution>1</resolution>
                      <min_angle>-0.785</min_angle>
                      <max_angle>0.785</max_angle>
                  </vertical>
              </scan>
              <range>
                  <min>0.8</min>
                  <max>30</max>--><!--<Extracted from Simon dataset >-->
                  <!--<resolution>0.01</resolution>
              </range>
              <noise>
                  <type>gaussian</type>
                  <mean>0</mean>
                  <stddev>0.03</stddev>
              </noise>
          </ray>
    </sensor>-->

    </link>

    <link name="rotor_0">
      <pose frame="">0.09 -0.09 -0.005 0 0 0</pose>
      <inertial>
        <mass>0.005</mass>
        <inertia>
          <ixx>9.75e-07</ixx>
          <ixy>0</ixy>
          <ixz>0</ixz>
          <iyy>8.13545e-05</iyy>
          <iyz>0</iyz>
          <izz>8.22545e-05</izz>
        </inertia>
      </inertial>
      <visual name="rotor_0_visual">
        <geometry>
          <mesh>
            <uri>meshes/propeller_ccw.dae</uri>
          </mesh>
        </geometry>
        <material>
          <diffuse>1 0 0 1</diffuse>
          <script>
            <name>Gazebo/Red</name>
            <uri>file://media/materials/scripts/gazebo.material</uri>
          </script>
        </material>
        <cast_shadows>0</cast_shadows>
      </visual>
      <gravity>1</gravity>
      <velocity_decay/>
    </link>
    <joint name="rotor_0_joint" type="revolute">
      <child>rotor_0</child>
      <parent>body</parent>
      <axis>
        <xyz>0 0 1</xyz>
        <limit>
          <lower>-1e+16</lower>
          <upper>1e+16</upper>
        </limit>
        <dynamics>
          <spring_reference>0</spring_reference>
          <spring_stiffness>0</spring_stiffness>
        </dynamics>
        <use_parent_model_frame>1</use_parent_model_frame>
      </axis>
    </joint>

    <link name="rotor_1">
      <pose frame="">-0.09 0.09 0.05 0 0 0</pose>
      <inertial>
        <mass>0.005</mass>
        <inertia>
          <ixx>9.75e-07</ixx>
          <ixy>0</ixy>
          <ixz>0</ixz>
          <iyy>8.13545e-05</iyy>
          <iyz>0</iyz>
          <izz>8.22545e-05</izz>
        </inertia>
      </inertial>
      <visual name="rotor_1_visual">
        <geometry>
          <mesh>
            <uri>meshes/propeller_ccw.dae</uri>
          </mesh>
        </geometry>
        <material>
          <diffuse>0 0 1 1</diffuse>
          <script>
            <name>Gazebo/Blue</name>
            <uri>file://media/materials/scripts/gazebo.material</uri>
          </script>
        </material>
        <cast_shadows>0</cast_shadows>
      </visual>
      <gravity>1</gravity>
      <velocity_decay/>
    </link>
    <joint name="rotor_1_joint" type="revolute">
      <child>rotor_1</child>
      <parent>body</parent>
      <axis>
        <xyz>0 0 1</xyz>
        <limit>
          <lower>-1e+16</lower>
          <upper>1e+16</upper>
        </limit>
        <dynamics>
          <spring_reference>0</spring_reference>
          <spring_stiffness>0</spring_stiffness>
        </dynamics>
        <use_parent_model_frame>1</use_parent_model_frame>
      </axis>
    </joint>

    <link name="rotor_2">
      <pose frame="">0.09 0.09 -0.005 0 0 0</pose>
      <inertial>
        <mass>0.005</mass>
        <inertia>
          <ixx>9.75e-07</ixx>
          <ixy>0</ixy>
          <ixz>0</ixz>
          <iyy>8.13545e-05</iyy>
          <iyz>0</iyz>
          <izz>8.22545e-05</izz>
        </inertia>
      </inertial>
      <visual name="rotor_2_visual">
        <geometry>
          <mesh>
            <uri>meshes/propeller_cw.dae</uri>
          </mesh>
        </geometry>
        <material>
          <diffuse>1 0 0 1</diffuse>
          <script>
            <name>Gazebo/Red</name>
            <uri>file://media/materials/scripts/gazebo.material</uri>
          </script>
        </material>
        <cast_shadows>0</cast_shadows>
      </visual>
      <gravity>1</gravity>
      <velocity_decay/>
    </link>
    <joint name="rotor_2_joint" type="revolute">
      <child>rotor_2</child>
      <parent>body</parent>
      <axis>
        <xyz>0 0 1</xyz>
        <limit>
          <lower>-1e+16</lower>
          <upper>1e+16</upper>
        </limit>
        <dynamics>
          <spring_reference>0</spring_reference>
          <spring_stiffness>0</spring_stiffness>
        </dynamics>
        <use_parent_model_frame>1</use_parent_model_frame>
      </axis>
    </joint>

    <link name="rotor_3">
      <pose frame="">-0.09 -0.09 0.05 0 0 0</pose>
      <inertial>
        <mass>0.005</mass>
        <inertia>
          <ixx>9.75e-07</ixx>
          <ixy>0</ixy>
          <ixz>0</ixz>
          <iyy>8.13545e-05</iyy>
          <iyz>0</iyz>
          <izz>8.22545e-05</izz>
        </inertia>
      </inertial>
      <visual name="rotor_3_visual">
        <geometry>
          <mesh>
            <uri>meshes/propeller_cw.dae</uri>
          </mesh>
        </geometry>
        <material>
          <diffuse>0 0 1 1</diffuse>
          <script>
            <name>Gazebo/Blue</name>
            <uri>file://media/materials/scripts/gazebo.material</uri>
          </script>
        </material>
        <cast_shadows>0</cast_shadows>
      </visual>
      <gravity>1</gravity>
      <velocity_decay/>
    </link>
    <joint name="rotor_3_joint" type="revolute">
      <child>rotor_3</child>
      <parent>body</parent>
      <axis>
        <xyz>0 0 1</xyz>
        <limit>
          <lower>-1e+16</lower>
          <upper>1e+16</upper>
        </limit>
        <dynamics>
          <spring_reference>0</spring_reference>
          <spring_stiffness>0</spring_stiffness>
        </dynamics>
        <use_parent_model_frame>1</use_parent_model_frame>
      </axis>
    </joint>

    <plugin filename="libignition-gazebo-pose-publisher-system.so" name="ignition::gazebo::systems::PosePublisher">
      <publish_link_pose>true</publish_link_pose>
      <publish_sensor_pose>true</publish_sensor_pose>
      <publish_collision_pose>false</publish_collision_pose>
      <publish_visual_pose>false</publish_visual_pose>
      <publish_nested_model_pose>true</publish_nested_model_pose>
      <use_pose_vector_msg>true</use_pose_vector_msg>
      <static_publisher>false</static_publisher>
    </plugin>

    <plugin filename="libgazebo_barometer_plugin.so" name="barometer_plugin::BarometerPlugin">
      <link_name>body</link_name>
    </plugin>
    <plugin filename="libgazebo_gps_plugin.so" name="gps_plugin::GpsPlugin">
      <link_name>body</link_name>
    </plugin>
    <plugin filename="libgazebo_magnetometer_plugin.so" name="magnetometer_plugin::MagnetometerPlugin">
      <link_name>body</link_name>
    </plugin>

    <plugin filename="ignition-gazebo-multicopter-motor-model-system" name="ignition::gazebo::systems::MulticopterMotorModel">
      <robotNamespace>rmf_owl</robotNamespace>
      <jointName>rotor_0_joint</jointName>
      <linkName>rotor_0</linkName>
      <turningDirection>ccw</turningDirection>
      <timeConstantUp>0.0125</timeConstantUp>
      <timeConstantDown>0.025</timeConstantDown>
      <maxRotVelocity>800.0</maxRotVelocity>
      <motorConstant>8.54858e-06</motorConstant>
      <momentConstant>0.016</momentConstant>
      <commandSubTopic>gazebo/command/motor_speed</commandSubTopic>
      <motorNumber>0</motorNumber>
      <rotorDragCoefficient>8.06428e-05</rotorDragCoefficient>
      <rollingMomentCoefficient>1e-06</rollingMomentCoefficient>
      <motorSpeedPubTopic>motor_speed/0</motorSpeedPubTopic>
      <rotorVelocitySlowdownSim>10</rotorVelocitySlowdownSim>
      <motorType>velocity</motorType>
    </plugin>

    <plugin filename="ignition-gazebo-multicopter-motor-model-system" name="ignition::gazebo::systems::MulticopterMotorModel">
      <robotNamespace>rmf_owl</robotNamespace>
      <jointName>rotor_1_joint</jointName>
      <linkName>rotor_1</linkName>
      <turningDirection>ccw</turningDirection>
      <timeConstantUp>0.0125</timeConstantUp>
      <timeConstantDown>0.025</timeConstantDown>
      <maxRotVelocity>800.0</maxRotVelocity>
      <motorConstant>8.54858e-06</motorConstant>
      <momentConstant>0.016</momentConstant>
      <commandSubTopic>gazebo/command/motor_speed</commandSubTopic>
      <motorNumber>1</motorNumber>
      <rotorDragCoefficient>8.06428e-05</rotorDragCoefficient>
      <rollingMomentCoefficient>1e-06</rollingMomentCoefficient>
      <motorSpeedPubTopic>motor_speed/1</motorSpeedPubTopic>
      <rotorVelocitySlowdownSim>10</rotorVelocitySlowdownSim>
      <motorType>velocity</motorType>
    </plugin>

    <plugin filename="ignition-gazebo-multicopter-motor-model-system" name="ignition::gazebo::systems::MulticopterMotorModel">
      <robotNamespace>rmf_owl</robotNamespace>
      <jointName>rotor_2_joint</jointName>
      <linkName>rotor_2</linkName>
      <turningDirection>cw</turningDirection>
      <timeConstantUp>0.0125</timeConstantUp>
      <timeConstantDown>0.025</timeConstantDown>
      <maxRotVelocity>800.0</maxRotVelocity>
      <motorConstant>8.54858e-06</motorConstant>
      <momentConstant>0.016</momentConstant>
      <commandSubTopic>gazebo/command/motor_speed</commandSubTopic>
      <motorNumber>2</motorNumber>
      <rotorDragCoefficient>8.06428e-05</rotorDragCoefficient>
      <rollingMomentCoefficient>1e-06</rollingMomentCoefficient>
      <motorSpeedPubTopic>motor_speed/2</motorSpeedPubTopic>
      <rotorVelocitySlowdownSim>10</rotorVelocitySlowdownSim>
      <motorType>velocity</motorType>
    </plugin>

    <plugin filename="ignition-gazebo-multicopter-motor-model-system" name="ignition::gazebo::systems::MulticopterMotorModel">
      <robotNamespace>rmf_owl</robotNamespace>
      <jointName>rotor_3_joint</jointName>
      <linkName>rotor_3</linkName>
      <turningDirection>cw</turningDirection>
      <timeConstantUp>0.0125</timeConstantUp>
      <timeConstantDown>0.025</timeConstantDown>
      <maxRotVelocity>800.0</maxRotVelocity>
      <motorConstant>8.54858e-06</motorConstant>
      <momentConstant>0.016</momentConstant>
      <commandSubTopic>gazebo/command/motor_speed</commandSubTopic>
      <motorNumber>3</motorNumber>
      <rotorDragCoefficient>8.06428e-05</rotorDragCoefficient>
      <rollingMomentCoefficient>1e-06</rollingMomentCoefficient>
      <motorSpeedPubTopic>motor_speed/3</motorSpeedPubTopic>
      <rotorVelocitySlowdownSim>10</rotorVelocitySlowdownSim>
      <motorType>velocity</motorType>
    </plugin>

    <plugin filename="libmavlink_sitl_ign_gazebo.so" name="mavlink_interface::GazeboMavlinkInterface">
      <robotNamespace>rmf_owl</robotNamespace>
      <imuSubTopic>/imu</imuSubTopic>
      <magSubTopic>/mag</magSubTopic>
      <baroSubTopic>/baro</baroSubTopic>
      <mavlink_addr>INADDR_ANY</mavlink_addr>
      <mavlink_udp_port>14560</mavlink_udp_port>
      <mavlink_tcp_port>4560</mavlink_tcp_port>
      <serialEnabled>0</serialEnabled>
      <serialDevice>/dev/ttyACM0</serialDevice>
      <baudRate>921600</baudRate>
      <qgc_addr>INADDR_ANY</qgc_addr>
      <qgc_udp_port>14550</qgc_udp_port>
      <sdk_addr>INADDR_ANY</sdk_addr>
      <sdk_udp_port>14540</sdk_udp_port>
      <hil_mode>0</hil_mode>
      <hil_state_level>0</hil_state_level>
      <vehicle_is_tailsitter>0</vehicle_is_tailsitter>
      <send_vision_estimation>0</send_vision_estimation>
      <send_odometry>1</send_odometry>
      <enable_lockstep>1</enable_lockstep>
      <use_tcp>1</use_tcp>
      <motorSpeedCommandPubTopic>/gazebo/command/motor_speed</motorSpeedCommandPubTopic>
      <control_channels>
        <channel name="rotor1">
          <input_index>0</input_index>
          <input_offset>0</input_offset>
          <input_scaling>1000</input_scaling>
          <zero_position_disarmed>0</zero_position_disarmed>
          <zero_position_armed>100</zero_position_armed>
          <joint_control_type>velocity</joint_control_type>
        </channel>
        <channel name="rotor2">
          <input_index>1</input_index>
          <input_offset>0</input_offset>
          <input_scaling>1000</input_scaling>
          <zero_position_disarmed>0</zero_position_disarmed>
          <zero_position_armed>100</zero_position_armed>
          <joint_control_type>velocity</joint_control_type>
        </channel>
        <channel name="rotor3">
          <input_index>2</input_index>
          <input_offset>0</input_offset>
          <input_scaling>1000</input_scaling>
          <zero_position_disarmed>0</zero_position_disarmed>
          <zero_position_armed>100</zero_position_armed>
          <joint_control_type>velocity</joint_control_type>
        </channel>
        <channel name="rotor4">
          <input_index>3</input_index>
          <input_offset>0</input_offset>
          <input_scaling>1000</input_scaling>
          <zero_position_disarmed>0</zero_position_disarmed>
          <zero_position_armed>100</zero_position_armed>
          <joint_control_type>velocity</joint_control_type>
        </channel>
        <channel name="rotor5">
          <input_index>4</input_index>
          <input_offset>1</input_offset>
          <input_scaling>324.6</input_scaling>
          <zero_position_disarmed>0</zero_position_disarmed>
          <zero_position_armed>0</zero_position_armed>
          <joint_control_type>velocity</joint_control_type>
          <joint_control_pid>
            <p>0.1</p>
            <i>0</i>
            <d>0</d>
            <iMax>0.0</iMax>
            <iMin>0.0</iMin>
            <cmdMax>2</cmdMax>
            <cmdMin>-2</cmdMin>
          </joint_control_pid>
          <joint_name>zephyr_delta_wing::propeller_joint</joint_name>
        </channel>
        <channel name="rotor6">
          <input_index>5</input_index>
          <input_offset>0</input_offset>
          <input_scaling>0.524</input_scaling>
          <zero_position_disarmed>0</zero_position_disarmed>
          <zero_position_armed>0</zero_position_armed>
          <joint_control_type>position</joint_control_type>
          <joint_name>zephyr_delta_wing::flap_left_joint</joint_name>
          <joint_control_pid>
            <p>10.0</p>
            <i>0</i>
            <d>0</d>
            <iMax>0</iMax>
            <iMin>0</iMin>
            <cmdMax>20</cmdMax>
            <cmdMin>-20</cmdMin>
          </joint_control_pid>
        </channel>
        <channel name="rotor7">
          <input_index>6</input_index>
          <input_offset>0</input_offset>
          <input_scaling>0.524</input_scaling>
          <zero_position_disarmed>0</zero_position_disarmed>
          <zero_position_armed>0</zero_position_armed>
          <joint_control_type>position</joint_control_type>
          <joint_name>zephyr_delta_wing::flap_right_joint</joint_name>
          <joint_control_pid>
            <p>10.0</p>
            <i>0</i>
            <d>0</d>
            <iMax>0</iMax>
            <iMin>0</iMin>
            <cmdMax>20</cmdMax>
            <cmdMin>-20</cmdMin>
          </joint_control_pid>
        </channel>
        <channel name="rotor8">
          <input_index>7</input_index>
          <input_offset>0</input_offset>
          <input_scaling>0.524</input_scaling>
          <zero_position_disarmed>0</zero_position_disarmed>
          <zero_position_armed>0</zero_position_armed>
          <joint_control_type>position</joint_control_type>
        </channel>
      </control_channels>
    </plugin>
  </model>
</sdf>
